<?xml version="1.0"?>
<robot xmlns:xacro="http://www.ros.org/wiki/xacro" name="quadcopter">

  <!-- xacro include filename="quad_include.xacro" -->

  <!-- First Link and the only joint -->
  <link name="map"></link>
  <joint name="base_joint" type="fixed">
    <!-- THe CoG of the quadcopter 7cm below of the quadcopter frame axis -->
    <origin xyz="0 0 0.05" rpy="0 0 0"/>
    <!--axis xyz="0 0 1"/>
    <limit upper="0.0" lower="3.14" effort="2" velocity="2.0"/-->
    <parent link="map"/>
    <child link="base_link"/>
  </joint>
  
  <!--Base Floor-->
	  <link name="base_link">
	  <static>true</static>
        <visual>
            <origin xyz="0 0 0.05" rpy="0 0 0"/>
            <geometry>
                <box size="2.5 1.5 0.1" />
            </geometry>
            <material name="green">
                <color rgba="0.2 1 0.2 1"/>
            </material>
        </visual>
        <collision>
            <origin xyz="0 0 0.05" rpy="0 0 0"/>
            <geometry>
                <box size="2.5 1.5 0.1" />
            </geometry>
        </collision>
        <inertial>
            <origin xyz="0 0 0.05" rpy="0 0 0"/>
            <mass value="12" />
            <inertia ixx="2.26" ixy="0.0" ixz="0.0" iyy="6.26" iyz="0.0" izz="8.5" />
        </inertial>
</link>

  <!--Base to Quadcopter Joint -->
  <joint name="quad_joint" type="prismatic">
        <origin xyz="-1.25 0 0.075" rpy="0 0 0"/>
        <parent link="base_link"/>
        <child link="quad_link"/>
        <axis xyz="1 0 0"/>
        <limit lower="0" upper="2" velocity="100" effort="100"/>
</joint>

  <!-- Quadcopter Description -->
  <link name="quad_link">
    <visual name="quad_blend">
      <origin xyz="0 0 0.075" rpy="0 0 0"/>
      <geometry>
	      <mesh filename="package://quad_sim/quadcopter/meshes/quad.dae"/>
      </geometry>
    </visual>
    <collision>
      <origin xyz="0 0 0.075" rpy="0 0 0"/>
      <geometry>
	      <mesh filename="package://quad_sim/quadcopter/meshes/quad.stl"/>
      </geometry>
    </collision>
    <inertial>
      <origin xyz="0 0 0.075" rpy="0 0 0"/>
      <mass value="0.4"/>
      <inertia ixx="0.0038278" ixy="0.0" ixz="0.0" iyy="0.0038278" iyz="0.0" izz="0.0071345"/>
    </inertial>
  </link>

  <!--transmission name="trans1">
	  <type>transmission_interface/SimpleTransmission</type>
	  <joint name="quad_joint">
		  <hardwareInterface>EffortJointInterface</hardwareInterface>
	  </joint>
	  <actuator>
		  <hardwareInterface>EffortJointInterface</hardwareInterface>
	  </actuator>
  </transmission-->

  <!-- xacro:include filename="world.xacro" -->

</robot>
